2025-05-25 23:59:24,232 INFO    MainThread:30276 [wandb_setup.py:_flush():68] Current SDK version is 0.19.10
2025-05-25 23:59:24,232 INFO    MainThread:30276 [wandb_setup.py:_flush():68] Configure stats pid to 30276
2025-05-25 23:59:24,232 INFO    MainThread:30276 [wandb_setup.py:_flush():68] Loading settings from C:\Users\Zll11\.config\wandb\settings
2025-05-25 23:59:24,232 INFO    MainThread:30276 [wandb_setup.py:_flush():68] Loading settings from D:\TU-Delft\Tech_star\repo_test\Energydiff\diffusion_again\wandb\settings
2025-05-25 23:59:24,232 INFO    MainThread:30276 [wandb_setup.py:_flush():68] Loading settings from environment variables
2025-05-25 23:59:24,233 INFO    MainThread:30276 [wandb_init.py:setup_run_log_directory():724] Logging user logs to D:\TU-Delft\Tech_star\repo_test\Energydiff\diffusion_again\wandb\run-20250525_235924-7n5630e3\logs\debug.log
2025-05-25 23:59:24,234 INFO    MainThread:30276 [wandb_init.py:setup_run_log_directory():725] Logging internal logs to D:\TU-Delft\Tech_star\repo_test\Energydiff\diffusion_again\wandb\run-20250525_235924-7n5630e3\logs\debug-internal.log
2025-05-25 23:59:24,234 INFO    MainThread:30276 [wandb_init.py:init():852] calling init triggers
2025-05-25 23:59:24,234 INFO    MainThread:30276 [wandb_init.py:init():857] wandb.init called with sweep_config: {}
config: {'experiment': 'wind_transformer_diffusion', 'model': {'input_dim': 7, 'model_dim': 256, 'seq_len': 48, 'timesteps': 200, 'num_layers': 6, 'dropout': 0.1}, 'training': {'batch_size': 64, 'epochs': 100, 'lr': '1e-4', 'optimizer': 'adamw'}, 'loss': {'type': 'mse'}, 'sample': {'n_samples': 1000, 'save_path': 'samples/'}, '_wandb': {}}
2025-05-25 23:59:24,234 INFO    MainThread:30276 [wandb_init.py:init():893] starting backend
2025-05-25 23:59:24,234 INFO    MainThread:30276 [wandb_init.py:init():897] sending inform_init request
2025-05-25 23:59:24,252 INFO    MainThread:30276 [backend.py:_multiprocessing_setup():101] multiprocessing start_methods=spawn, using: spawn
2025-05-25 23:59:24,252 INFO    MainThread:30276 [wandb_init.py:init():907] backend started and connected
2025-05-25 23:59:24,255 INFO    MainThread:30276 [wandb_init.py:init():1002] updated telemetry
2025-05-25 23:59:24,279 INFO    MainThread:30276 [wandb_init.py:init():1026] communicating run to backend with 90.0 second timeout
2025-05-25 23:59:24,749 INFO    MainThread:30276 [wandb_init.py:init():1101] starting run threads in backend
2025-05-25 23:59:24,805 INFO    MainThread:30276 [wandb_run.py:_console_start():2566] atexit reg
2025-05-25 23:59:24,805 INFO    MainThread:30276 [wandb_run.py:_redirect():2414] redirect: wrap_raw
2025-05-25 23:59:24,805 INFO    MainThread:30276 [wandb_run.py:_redirect():2483] Wrapping output streams.
2025-05-25 23:59:24,805 INFO    MainThread:30276 [wandb_run.py:_redirect():2506] Redirects installed.
2025-05-25 23:59:24,806 INFO    MainThread:30276 [wandb_init.py:init():1147] run started, returning control to user process
2025-05-26 02:33:56,627 WARNING MsgRouterThr:30276 [router.py:message_loop():63] [no run ID] message_loop has been closed
Traceback (most recent call last):
  File "D:\TU-Delft\Tech_star\venv\Lib\site-packages\wandb\sdk\lib\sock_client.py", line 208, in _read_packet_bytes
    data = self._sock.recv(self._bufsize)
           ^^^^^^^^^^^^^^^^^^^^^^^^^^^^^^
ConnectionResetError: [WinError 10054] 远程主机强迫关闭了一个现有的连接。

The above exception was the direct cause of the following exception:

Traceback (most recent call last):
  File "D:\TU-Delft\Tech_star\venv\Lib\site-packages\wandb\sdk\interface\router_sock.py", line 27, in _read_message
    return self._sock_client.read_server_response(timeout=1)
           ^^^^^^^^^^^^^^^^^^^^^^^^^^^^^^^^^^^^^^^^^^^^^^^^^
  File "D:\TU-Delft\Tech_star\venv\Lib\site-packages\wandb\sdk\lib\sock_client.py", line 235, in read_server_response
    data = self._read_packet_bytes(timeout=timeout)
           ^^^^^^^^^^^^^^^^^^^^^^^^^^^^^^^^^^^^^^^^
  File "D:\TU-Delft\Tech_star\venv\Lib\site-packages\wandb\sdk\lib\sock_client.py", line 212, in _read_packet_bytes
    raise SockClientClosedError from e
wandb.sdk.lib.sock_client.SockClientClosedError

The above exception was the direct cause of the following exception:

Traceback (most recent call last):
  File "D:\TU-Delft\Tech_star\venv\Lib\site-packages\wandb\sdk\interface\router.py", line 56, in message_loop
    msg = self._read_message()
          ^^^^^^^^^^^^^^^^^^^^
  File "D:\TU-Delft\Tech_star\venv\Lib\site-packages\wandb\sdk\interface\router_sock.py", line 29, in _read_message
    raise MessageRouterClosedError from e
wandb.sdk.interface.router.MessageRouterClosedError
2025-05-26 02:33:56,643 INFO    MsgRouterThr:30276 [mailbox.py:close():129] [no run ID] Closing mailbox, abandoning 1 handles.
